2018-01-08 20:03:00,342 ERROR: Exception on /explore [GET] [in /home/jb/.virtualenvs/flask_mega_tutorial/lib/python3.5/site-packages/flask/app.py:1560]
Traceback (most recent call last):
  File "/home/jb/.virtualenvs/flask_mega_tutorial/lib/python3.5/site-packages/flask/app.py", line 1982, in wsgi_app
    response = self.full_dispatch_request()
  File "/home/jb/.virtualenvs/flask_mega_tutorial/lib/python3.5/site-packages/flask/app.py", line 1614, in full_dispatch_request
    rv = self.handle_user_exception(e)
  File "/home/jb/.virtualenvs/flask_mega_tutorial/lib/python3.5/site-packages/flask/app.py", line 1517, in handle_user_exception
    reraise(exc_type, exc_value, tb)
  File "/home/jb/.virtualenvs/flask_mega_tutorial/lib/python3.5/site-packages/flask/_compat.py", line 33, in reraise
    raise value
  File "/home/jb/.virtualenvs/flask_mega_tutorial/lib/python3.5/site-packages/flask/app.py", line 1612, in full_dispatch_request
    rv = self.dispatch_request()
  File "/home/jb/.virtualenvs/flask_mega_tutorial/lib/python3.5/site-packages/flask/app.py", line 1598, in dispatch_request
    return self.view_functions[rule.endpoint](**req.view_args)
  File "/home/jb/.virtualenvs/flask_mega_tutorial/lib/python3.5/site-packages/flask_login/utils.py", line 261, in decorated_view
    return func(*args, **kwargs)
  File "/home/jb/git_local/microblog/app/routes.py", line 136, in explore
    page, app.config['POSTS_PER_PAGE'], FALSE)
NameError: name 'FALSE' is not defined
2018-01-08 20:03:12,302 ERROR: Exception on /explore [GET] [in /home/jb/.virtualenvs/flask_mega_tutorial/lib/python3.5/site-packages/flask/app.py:1560]
Traceback (most recent call last):
  File "/home/jb/.virtualenvs/flask_mega_tutorial/lib/python3.5/site-packages/flask/app.py", line 1982, in wsgi_app
    response = self.full_dispatch_request()
  File "/home/jb/.virtualenvs/flask_mega_tutorial/lib/python3.5/site-packages/flask/app.py", line 1614, in full_dispatch_request
    rv = self.handle_user_exception(e)
  File "/home/jb/.virtualenvs/flask_mega_tutorial/lib/python3.5/site-packages/flask/app.py", line 1517, in handle_user_exception
    reraise(exc_type, exc_value, tb)
  File "/home/jb/.virtualenvs/flask_mega_tutorial/lib/python3.5/site-packages/flask/_compat.py", line 33, in reraise
    raise value
  File "/home/jb/.virtualenvs/flask_mega_tutorial/lib/python3.5/site-packages/flask/app.py", line 1612, in full_dispatch_request
    rv = self.dispatch_request()
  File "/home/jb/.virtualenvs/flask_mega_tutorial/lib/python3.5/site-packages/flask/app.py", line 1598, in dispatch_request
    return self.view_functions[rule.endpoint](**req.view_args)
  File "/home/jb/.virtualenvs/flask_mega_tutorial/lib/python3.5/site-packages/flask_login/utils.py", line 261, in decorated_view
    return func(*args, **kwargs)
  File "/home/jb/git_local/microblog/app/routes.py", line 136, in explore
    page, app.config['POSTS_PER_PAGE'], FALSE)
NameError: name 'FALSE' is not defined
2018-01-08 20:03:27,914 ERROR: Exception on /explore [GET] [in /home/jb/.virtualenvs/flask_mega_tutorial/lib/python3.5/site-packages/flask/app.py:1560]
Traceback (most recent call last):
  File "/home/jb/.virtualenvs/flask_mega_tutorial/lib/python3.5/site-packages/flask/app.py", line 1982, in wsgi_app
    response = self.full_dispatch_request()
  File "/home/jb/.virtualenvs/flask_mega_tutorial/lib/python3.5/site-packages/flask/app.py", line 1614, in full_dispatch_request
    rv = self.handle_user_exception(e)
  File "/home/jb/.virtualenvs/flask_mega_tutorial/lib/python3.5/site-packages/flask/app.py", line 1517, in handle_user_exception
    reraise(exc_type, exc_value, tb)
  File "/home/jb/.virtualenvs/flask_mega_tutorial/lib/python3.5/site-packages/flask/_compat.py", line 33, in reraise
    raise value
  File "/home/jb/.virtualenvs/flask_mega_tutorial/lib/python3.5/site-packages/flask/app.py", line 1612, in full_dispatch_request
    rv = self.dispatch_request()
  File "/home/jb/.virtualenvs/flask_mega_tutorial/lib/python3.5/site-packages/flask/app.py", line 1598, in dispatch_request
    return self.view_functions[rule.endpoint](**req.view_args)
  File "/home/jb/.virtualenvs/flask_mega_tutorial/lib/python3.5/site-packages/flask_login/utils.py", line 261, in decorated_view
    return func(*args, **kwargs)
  File "/home/jb/git_local/microblog/app/routes.py", line 136, in explore
    page, app.config['POSTS_PER_PAGE'], FALSE)
NameError: name 'FALSE' is not defined
2018-01-08 20:03:34,699 ERROR: Exception on /explore [GET] [in /home/jb/.virtualenvs/flask_mega_tutorial/lib/python3.5/site-packages/flask/app.py:1560]
Traceback (most recent call last):
  File "/home/jb/.virtualenvs/flask_mega_tutorial/lib/python3.5/site-packages/flask/app.py", line 1982, in wsgi_app
    response = self.full_dispatch_request()
  File "/home/jb/.virtualenvs/flask_mega_tutorial/lib/python3.5/site-packages/flask/app.py", line 1614, in full_dispatch_request
    rv = self.handle_user_exception(e)
  File "/home/jb/.virtualenvs/flask_mega_tutorial/lib/python3.5/site-packages/flask/app.py", line 1517, in handle_user_exception
    reraise(exc_type, exc_value, tb)
  File "/home/jb/.virtualenvs/flask_mega_tutorial/lib/python3.5/site-packages/flask/_compat.py", line 33, in reraise
    raise value
  File "/home/jb/.virtualenvs/flask_mega_tutorial/lib/python3.5/site-packages/flask/app.py", line 1612, in full_dispatch_request
    rv = self.dispatch_request()
  File "/home/jb/.virtualenvs/flask_mega_tutorial/lib/python3.5/site-packages/flask/app.py", line 1598, in dispatch_request
    return self.view_functions[rule.endpoint](**req.view_args)
  File "/home/jb/.virtualenvs/flask_mega_tutorial/lib/python3.5/site-packages/flask_login/utils.py", line 261, in decorated_view
    return func(*args, **kwargs)
  File "/home/jb/git_local/microblog/app/routes.py", line 136, in explore
    page, app.config['POSTS_PER_PAGE'], FALSE)
NameError: name 'FALSE' is not defined
2018-01-08 20:03:38,862 ERROR: Exception on /explore [GET] [in /home/jb/.virtualenvs/flask_mega_tutorial/lib/python3.5/site-packages/flask/app.py:1560]
Traceback (most recent call last):
  File "/home/jb/.virtualenvs/flask_mega_tutorial/lib/python3.5/site-packages/flask/app.py", line 1982, in wsgi_app
    response = self.full_dispatch_request()
  File "/home/jb/.virtualenvs/flask_mega_tutorial/lib/python3.5/site-packages/flask/app.py", line 1614, in full_dispatch_request
    rv = self.handle_user_exception(e)
  File "/home/jb/.virtualenvs/flask_mega_tutorial/lib/python3.5/site-packages/flask/app.py", line 1517, in handle_user_exception
    reraise(exc_type, exc_value, tb)
  File "/home/jb/.virtualenvs/flask_mega_tutorial/lib/python3.5/site-packages/flask/_compat.py", line 33, in reraise
    raise value
  File "/home/jb/.virtualenvs/flask_mega_tutorial/lib/python3.5/site-packages/flask/app.py", line 1612, in full_dispatch_request
    rv = self.dispatch_request()
  File "/home/jb/.virtualenvs/flask_mega_tutorial/lib/python3.5/site-packages/flask/app.py", line 1598, in dispatch_request
    return self.view_functions[rule.endpoint](**req.view_args)
  File "/home/jb/.virtualenvs/flask_mega_tutorial/lib/python3.5/site-packages/flask_login/utils.py", line 261, in decorated_view
    return func(*args, **kwargs)
  File "/home/jb/git_local/microblog/app/routes.py", line 136, in explore
    page, app.config['POSTS_PER_PAGE'], FALSE)
NameError: name 'FALSE' is not defined
2018-01-08 20:04:18,667 INFO: Microblog startup [in /home/jb/git_local/microblog/app/__init__.py:43]
2018-01-08 20:37:57,828 INFO: Microblog startup [in /home/jb/git_local/microblog/app/__init__.py:43]
2018-01-08 20:46:53,547 INFO: Microblog startup [in /home/jb/git_local/microblog/app/__init__.py:43]
2018-01-08 20:51:41,343 INFO: Microblog startup [in /home/jb/git_local/microblog/app/__init__.py:43]
2018-01-08 20:55:32,534 INFO: Microblog startup [in /home/jb/git_local/microblog/app/__init__.py:43]
2018-01-08 20:59:25,061 INFO: Microblog startup [in /home/jb/git_local/microblog/app/__init__.py:43]
